Workbook

Sheet Лист2
A1: ХП:Категория | H1: LED Candle Tail 12W 6500K E14 SALID^ | I1: SKU 1 | J1: 1.41
A2: Alyumin Profil Salid | B2: Category 1 | H2: Xrustal galogen orqa | I2: SKU 2 | J2: .6
A3: Xrustal plafon oddiy | B3: Category 2 | H3: Xrustal galogen driver | I3: SKU 3 | J3: .41
A4: Magnitniy Track Dusel | B4: Category 3 | H4: Uglovoy soedinitel dlya vnutrenniy rels | I4: SKU 4 | J4: 5.01
A5: Zapchastlar | B5: Category 4 | H5: Trekoviy magnitniy svetilnik tonkiy trek 18W F60 6500K | I5: SKU 5 | J5: 9.51
A6: Salid Candle | B6: Category 5 | H6: Trekoviy magnitniy svetilnik tonkiy trek 18W F60 4000K | I6: SKU 6 | J6: 9.51
H7: Trekoviy magnitniy svetilnik tonkiy trek 12W F50 6500K | I7: SKU 7 | J7: 6.01
H8: Trekoviy magnitniy svetilnik matoviy 36W L900 6500K | I8: SKU 8 | J8: 9.01
H9: Trekoviy magnitniy svetilnik matoviy 24W L600 6500K | I9: SKU 9 | J9: 6.21
H10: Trekoviy magnitniy svetilnik matoviy 24W L600 4000K | I10: SKU 10 | J10: 5.71
H11: Trekoviy magnitniy svetilnik matoviy 12W L300 6500K | I11: SKU 11 | J11: 3.51
H12: Soedinitel uglovoy dlya magnitniy svetilnik | I12: SKU 12 | J12: 3.01
H13: Soedinitel pryamoy dlya magnitniy svetilnik | I13: SKU 13 | J13: 2.01
H14: SH16-40 48W RGB shisha plafon | I14: SKU 14 | J14: 8.01
H15: SH15-40 48W BLUE shisha plafon | I15: SKU 15 | J15: 8.01
H16: SH14-40 48W GREEN shisha plafon | I16: SKU 16 | J16: 8.01
H17: SH13-40 48W RGB shisha plafon | I17: SKU 17 | J17: 8.01
H18: SH12-40 48W BLUE shisha plafon | I18: SKU 18 | J18: 8.01
... H52: Alyumin Profil-002 3Metr Salid | I52: SKU 52 | J52: 3.31
H53: Alyumin Profil-001 3Metr Salid | I53: SKU 53 | J53: 3.31

Sheet Reja
B2: Mijozlar analizlari va RFM tahlil
C4: Maqsad: Mijozlar ma’lumotlarini tahlil qilib, ularni RFM modeli asosida guruhlarga ajratish va biznes qarorlar chiqarishni o‘rganish.
D6: Mijozlar tahlili nima uchun kerak?
D7: Sodiq mijozlarni topish
D8: Yo‘qotilayotgan mijozlarni qaytarish
D9: Reklama va aksiyalarni to‘g‘ri yo‘naltirish
D10: RFM tushunchasi:
D11: R – Recency (oxirgi xarid qachon bo‘lgan?)
D12: F – Frequency (necha marta xarid qilgan?)
D13: M – Monetary (qancha pul sarflagan?)
E15: Amaliy qadamlar
E16: 1. Ma’lumotlarni tayyorlash
E17: Har bir mijoz bo‘yicha oxirgi xarid sanasi topiladi (Recency)
E18: Xaridlar soni hisoblanadi (Frequency)
E19: Xarid summasi hisoblanadi (Monetary)
E20: 2. RFM qiymatlarini hisoblash
E21: Recency → bugungi sana – oxirgi xarid sanasi
E22: Frequency → buyurtmalar soni
E23: Monetary → umumiy xarajat
E24: 3. Kvantil bo‘yicha ball berish (1–5)
E25: Recency: eng tez-tez keladigan mijozlar 5 ball
E26: Frequency: eng ko‘p xarid qilganlar 5 ball
... E32: Potensial yo‘qotishdagi mijozlar: R=1–2, M=4–5
F34: Yakuniy xulosa
F35: Har bir segment bo‘yicha marketing strategiya misollari:
F36: Top mijozlar → VIP takliflar, maxsus chegirmalar
F37: Yangi mijozlar → xush kelibsiz aksiyalar
F38: Yo‘qotilayotgan mijozlar → qaytarish uchun promo kodlar

Sheet Data
A1: Организация | B1: Дата отгрузки | C1: Месяц | D1: Рабочая зона | E1: ИД клиента | F1: Категории клиент | G1: Категория товара | H1: SKU | I1: Цена с переоценкой | J1: Сумма продажи | K1: Сумма скидки/наценки | L1: Количество продажи
A2: Toshkent | B2: 45631 | C2: =MONTH(B2) -> 12 | D2: ТП-34 | E2: 6137985 | F2: Другие | G2: Category 2 | H2: SKU 21 | I2: 125766.44 | J2: 251532.88 | L2: 2
A3: Toshkent | B3: 45633 | C3: =MONTH(B3) -> 12 | D3: ТП-118 | E3: 6080604 | F3: Другие | G3: Category 5 | H3: SKU 41 | I3: 17715.353 | J3: 354307.06 | L3: 20
A4: Toshkent | B4: 45633 | C4: =MONTH(B4) -> 12 | D4: ТП-118 | E4: 6080604 | F4: Другие | G4: Category 5 | H4: SKU 1 | I4: 17715.353 | J4: 354307.06 | L4: 20
A5: Toshkent | B5: 45635 | C5: =MONTH(B5) -> 12 | D5: ТП-118 | E5: 6080604 | F5: Другие | G5: Category 5 | H5: SKU 41 | I5: 17715.353 | J5: 531460.58 | L5: 30
A6: Toshkent | B6: 45635 | C6: =MONTH(B6) -> 12 | D6: ТП-118 | E6: 6080604 | F6: Другие | G6: Category 5 | H6: SKU 1 | I6: 17715.353 | J6: 531460.58 | L6: 30
A7: Toshkent | B7: 45656 | C7: =MONTH(B7) -> 12 | D7: ТП-118 | E7: 4876516 | F7: Другие | G7: Category 5 | H7: SKU 42 | I7: 17715.353 | J7: -212584.23 | L7: -12
A8: Samarqand | B8: 45630 | C8: =MONTH(B8) -> 12 | D8: ТП-114 | E8: 4874448 | F8: Другие | G8: Category 1 | H8: SKU 50 | I8: 37817.881 | J8: 3781788.1 | L8: 100
A9: Samarqand | B9: 45631 | C9: =MONTH(B9) -> 12 | D9: ТП-96 | E9: 4876180 | F9: Другие | G9: Category 2 | H9: SKU 20 | I9: 100638.28 | J9: 402553.12 | L9: 4
A10: Samarqand | B10: 45631 | C10: =MONTH(B10) -> 12 | D10: ТП-96 | E10: 4876180 | F10: Другие | G10: Category 2 | H10: SKU 14 | I10: 100638.28 | J10: 402553.12 | L10: 4
A11: Samarqand | B11: 45636 | C11: =MONTH(B11) -> 12 | D11: ТП-119 | E11: 4876600 | F11: Другие | G11: Category 2 | H11: SKU 20 | I11: 100638.28 | J11: 402553.12 | L11: 4
A12: Samarqand | B12: 45636 | C12: =MONTH(B12) -> 12 | D12: ТП-119 | E12: 4876600 | F12: Другие | G12: Category 2 | H12: SKU 14 | I12: 100638.28 | J12: 1006382.8 | L12: 10
A13: Samarqand | B13: 45644 | C13: =MONTH(B13) -> 12 | D13: ТП-127 | E13: 4878657 | F13: Другие | G13: Category 2 | H13: SKU 28 | I13: 100638.28 | J13: 1006382.8 | K13: -43346.076 | L13: 10
A14: Samarqand | B14: 45644 | C14: =MONTH(B14) -> 12 | D14: ТП-127 | E14: 4878657 | F14: Другие | G14: Category 2 | H14: SKU 24 | I14: 100638.28 | J14: 603829.68 | K14: -26007.646 | L14: 6
A15: Samarqand | B15: 45645 | C15: =MONTH(B15) -> 12 | D15: ТП-62 | E15: 4876098 | F15: Другие | G15: Category 2 | H15: SKU 29 | I15: 125766.44 | J15: -125766.44 | L15: -1
A16: Samarqand | B16: 45645 | C16: =MONTH(B16) -> 12 | D16: ТП-62 | E16: 4876098 | F16: Другие | G16: Category 3 | H16: SKU 5 | I16: 119484.4 | J16: -119484.4 | L16: -1
A17: Samarqand | B17: 45648 | C17: =MONTH(B17) -> 12 | D17: ТП-62 | E17: 4876098 | F17: Другие | G17: Category 3 | H17: SKU 10 | I17: 71740.897 | J17: 1434817.9 | L17: 20
A18: Samarqand | B18: 45651 | C18: =MONTH(B18) -> 12 | D18: ТП-99 | E18: 4878586 | F18: Другие | G18: Category 2 | H18: SKU 14 | I18: 100638.28 | J18: -100638.28 | L18: -1
A19: Samarqand | B19: 45651 | C19: =MONTH(B19) -> 12 | D19: ТП-99 | E19: 4878586 | F19: Другие | G19: Category 2 | H19: SKU 29 | I19: 125766.44 | J19: -125766.44 | L19: -1
A20: Andijon | B20: 45627 | C20: =MONTH(B20) -> 12 | D20: ТП-41 | E20: 7787121 | F20: D | G20: Category 2 | H20: SKU 26 | I20: 100638.28 | J20: 201276.56 | K20: -8669.2152 | L20: 2
A21: Andijon | B21: 45627 | C21: =MONTH(B21) -> 12 | D21: ТП-41 | E21: 7787121 | F21: D | G21: Category 2 | H21: SKU 24 | I21: 100638.28 | J21: 201276.56 | K21: -8669.2152 | L21: 2
A22: Andijon | B22: 45627 | C22: =MONTH(B22) -> 12 | D22: ТП-41 | E22: 7787121 | F22: D | G22: Category 2 | H22: SKU 22 | I22: 100638.28 | J22: 201276.56 | K22: -8669.2152 | L22: 2
A23: Andijon | B23: 45627 | C23: =MONTH(B23) -> 12 | D23: ТП-41 | E23: 7787121 | F23: D | G23: Category 2 | H23: SKU 16 | I23: 100638.28 | J23: 201276.56 | K23: -8669.2152 | L23: 2
A24: Andijon | B24: 45627 | C24: =MONTH(B24) -> 12 | D24: ТП-41 | E24: 7787121 | F24: D | G24: Category 2 | H24: SKU 15 | I24: 100638.28 | J24: 201276.56 | K24: -8669.2152 | L24: 2
A25: Andijon | B25: 45627 | C25: =MONTH(B25) -> 12 | D25: ТП-41 | E25: 7787121 | F25: D | G25: Category 2 | H25: SKU 29 | I25: 125766.44 | J25: 125766.44 | K25: -5653.836 | L25: 1
A26: Andijon | B26: 45627 | C26: =MONTH(B26) -> 12 | D26: ТП-41 | E26: 7787121 | F26: D | G26: Category 2 | H26: SKU 23 | I26: 125766.44 | J26: 125766.44 | K26: -5653.836 | L26: 1
A27: Andijon | B27: 45627 | C27: =MONTH(B27) -> 12 | D27: ТП-41 | E27: 7503974 | F27: D | G27: Category 2 | H27: SKU 34 | I27: 100638.28 | J27: 402553.12 | L27: 4
A28: Andijon | B28: 45627 | C28: =MONTH(B28) -> 12 | D28: ТП-41 | E28: 7503974 | F28: D | G28: Category 2 | H28: SKU 32 | I28: 100638.28 | J28: -201276.56 | L28: -2
A29: Andijon | B29: 45627 | C29: =MONTH(B29) -> 12 | D29: ТП-41 | E29: 7503974 | F29: D | G29: Category 2 | H29: SKU 24 | I29: 100638.28 | J29: -402553.12 | L29: -4
A30: Andijon | B30: 45627 | C30: =MONTH(B30) -> 12 | D30: ТП-41 | E30: 7503974 | F30: D | G30: Category 2 | H30: SKU 22 | I30: 100638.28 | J30: -201276.56 | L30: -2
A31: Andijon | B31: 45627 | C31: =MONTH(B31) -> 12 | D31: ТП-41 | E31: 7503974 | F31: D | G31: Category 2 | H31: SKU 15 | I31: 100638.28 | J31: 402553.12 | L31: 4
A32: Andijon | B32: 45631 | C32: =MONTH(B32) -> 12 | D32: ТП-41 | E32: 7242425 | F32: B | G32: Category 2 | H32: SKU 32 | I32: 100638.28 | J32: 402553.12 | K32: -13870.744 | L32: 4
A33: Andijon | B33: 45631 | C33: =MONTH(B33) -> 12 | D33: ТП-41 | E33: 7242425 | F33: B | G33: Category 2 | H33: SKU 26 | I33: 100638.28 | J33: 402553.12 | K33: -13870.744 | L33: 4
A34: Andijon | B34: 45631 | C34: =MONTH(B34) -> 12 | D34: ТП-41 | E34: 7242425 | F34: B | G34: Category 2 | H34: SKU 24 | I34: 100638.28 | J34: 201276.56 | K34: -6935.3722 | L34: 2
A35: Andijon | B35: 45631 | C35: =MONTH(B35) -> 12 | D35: ТП-41 | E35: 7242425 | F35: B | G35: Category 2 | H35: SKU 22 | I35: 100638.28 | J35: 402553.12 | K35: -13870.744 | L35: 4
A36: Andijon | B36: 45631 | C36: =MONTH(B36) -> 12 | D36: ТП-41 | E36: 7242425 | F36: B | G36: Category 2 | H36: SKU 16 | I36: 100638.28 | J36: 201276.56 | K36: -6935.3722 | L36: 2
A37: Andijon | B37: 45631 | C37: =MONTH(B37) -> 12 | D37: ТП-41 | E37: 7242425 | F37: B | G37: Category 2 | H37: SKU 15 | I37: 100638.28 | J37: 402553.12 | K37: -13870.744 | L37: 4
A38: Andijon | B38: 45635 | C38: =MONTH(B38) -> 12 | D38: ТП-41 | E38: 7241129 | F38: D | G38: Category 1 | H38: SKU 51 | I38: 30279.433 | J38: 3027943.3 | K38: -90461.376 | L38: 100
A39: Andijon | B39: 45635 | C39: =MONTH(B39) -> 12 | D39: ТП-41 | E39: 8510405 | F39: D | G39: Category 2 | H39: SKU 26 | I39: 100638.28 | J39: 201276.56 | L39: 2
A40: Andijon | B40: 45643 | C40: =MONTH(B40) -> 12 | D40: ТП-41 | E40: 7907092 | F40: D | G40: Category 2 | H40: SKU 28 | I40: 100638.28 | J40: 2012765.6 | K40: -69353.722 | L40: 20
...

Sheet RFM mijozlar tahlili
C2: RFM qiymatlarni hisoblash | G2: Kvantil bo'yicha ball berish(1-5) | J2: R=5, F=5, M=5 | K2: R=4-5, F=4-5 | L2: R=1, F=1 | M2: R=1-3, M=3-5 | N2: 45566 | O2: Boshqa mijozlar
D3: =AVERAGE(D5:D534) -> 13.854717 | E3: =AVERAGE(E4:E534) -> 11386797 | J3: =COUNTIF(J5:J534,"TOP") -> 20 | K3: =COUNTIF(K5:K534,"Sodiq") -> 83 | L3: =COUNTIF(L5:L534, "Yo'qotilgan") -> 129 | M3: =COUNTIF(M5:M534,"Yo'qotishdagi") -> 90 | N3: =COUNTIF(N5:N534,"Yangi") -> 57 | O3: =SUM(J3:N3) -> 379
A4: Mijoz ID | B4: Birinchi harid | C4: Recency | D4: Frequency | E4: Monetary | F4: 45662 | G4: Recency | H4: Frequency | I4: Monetary | J4: Top mijozlar | K4: Sodiq Mijozlar | L4: Qaytib kelmaydiganlar | M4: Potensial yo'qotishdagi mijozlar | N4: Yangi mijozlar
A5: {=_xlfn.UNIQUE(Data!E2:E7344)} -> 6137985 | B5: =_xlfn.XLOOKUP(A5,Data!E:E,Data!B:B,0,0,-1) -> 45484 | C5: =_xlfn.XLOOKUP(A5,Data!E:E,Data!B:B) -> 45631 | D5: =COUNTIF(Data!E:E,A5) -> 12 | E5: =SUMIF(Data!E:E,'RFM mijozlar tahlili'!A5,Data!J:J) -> 2304491 | F5: =ROUND(($F$4-C5)/30,0) -> 1 | G5: =IF(F5<=1,5,IF(F5=2,4,IF(F5=3,3,IF(F5=4,2,IF(F5=5,1,IF(F5>5,0,0)))))) -> 5 | H5: =IF(D5>=$D$3,5,IF(D5<3,0,IF(D5<5,1,IF(D5<7,2,IF(D5<9,3,IF(D5<=$D$3,4,0)))))) -> 4 | I5: =IF(E5>=$E$3,5,IF(E5<2000000,0,IF(E5<=4000000,1,IF(E5<=6000000,2,IF(E5<=8000000,3,IF(E5<=$E$3,4)))))) -> 1 | J5: =IF(AND(G5=5,H5=5,I5=5),"TOP"," ") | K5: =IF(AND(G5>=4,H5>=4), "Sodiq", " ") -> Sodiq | L5: =IF(AND(G5<=1,H5<=1), "Yo'qotilgan", " ") | M5: =IF(AND(G5<=3,I5>=3), "Yo'qotishdagi", " ") | N5: =IF(AND((B5-$N$2)>0, F5<=2), "Yangi", " ")
A6: 6080604 | B6: =_xlfn.XLOOKUP(A6,Data!E:E,Data!B:B,0,0,-1) -> 45401 | C6: =_xlfn.XLOOKUP(A6,Data!E:E,Data!B:B) -> 45633 | D6: =COUNTIF(Data!E:E,A6) -> 27 | E6: =SUMIF(Data!E:E,'RFM mijozlar tahlili'!A6,Data!J:J) -> 14673966 | F6: =ROUND(($F$4-C6)/30,0) -> 1 | G6: =IF(F6<=1,5,IF(F6=2,4,IF(F6=3,3,IF(F6=4,2,IF(F6=5,1,IF(F6>5,0,0)))))) -> 5 | H6: =IF(D6>=$D$3,5,IF(D6<3,0,IF(D6<5,1,IF(D6<7,2,IF(D6<9,3,IF(D6<=$D$3,4,0)))))) -> 5 | I6: =IF(E6>=$E$3,5,IF(E6<2000000,0,IF(E6<=4000000,1,IF(E6<=6000000,2,IF(E6<=8000000,3,IF(E6<=$E$3,4)))))) -> 5 | J6: =IF(AND(G6=5,H6=5,I6=5),"TOP"," ") -> TOP | K6: =IF(AND(G6>=4,H6>=4), "Sodiq", " ") -> Sodiq | L6: =IF(AND(G6<=1,H6<=1), "Yo'qotilgan", " ") | M6: =IF(AND(G6<=3,I6>=3), "Yo'qotishdagi", " ") | N6: =IF(AND((B6-$N$2)>0, F6<=2), "Yangi", " ")
A7: 4876516 | B7: =_xlfn.XLOOKUP(A7,Data!E:E,Data!B:B,0,0,-1) -> 45614 | C7: =_xlfn.XLOOKUP(A7,Data!E:E,Data!B:B) -> 45656 | D7: =COUNTIF(Data!E:E,A7) -> 2 | E7: =SUMIF(Data!E:E,'RFM mijozlar tahlili'!A7,Data!J:J) -> 265730.29 | F7: =ROUND(($F$4-C7)/30,0) -> 0 | G7: =IF(F7<=1,5,IF(F7=2,4,IF(F7=3,3,IF(F7=4,2,IF(F7=5,1,IF(F7>5,0,0)))))) -> 5 | H7: =IF(D7>=$D$3,5,IF(D7<3,0,IF(D7<5,1,IF(D7<7,2,IF(D7<9,3,IF(D7<=$D$3,4,0)))))) -> 0 | I7: =IF(E7>=$E$3,5,IF(E7<2000000,0,IF(E7<=4000000,1,IF(E7<=6000000,2,IF(E7<=8000000,3,IF(E7<=$E$3,4)))))) -> 0 | J7: =IF(AND(G7=5,H7=5,I7=5),"TOP"," ") | K7: =IF(AND(G7>=4,H7>=4), "Sodiq", " ") | L7: =IF(AND(G7<=1,H7<=1), "Yo'qotilgan", " ") | M7: =IF(AND(G7<=3,I7>=3), "Yo'qotishdagi", " ") | N7: =IF(AND((B7-$N$2)>0, F7<=2), "Yangi", " ") -> Yangi
A8: 4874448 | B8: =_xlfn.XLOOKUP(A8,Data!E:E,Data!B:B,0,0,-1) -> 45525 | C8: =_xlfn.XLOOKUP(A8,Data!E:E,Data!B:B) -> 45630 | D8: =COUNTIF(Data!E:E,A8) -> 3 | E8: =SUMIF(Data!E:E,'RFM mijozlar tahlili'!A8,Data!J:J) -> 3781788.1 | F8: =ROUND(($F$4-C8)/30,0) -> 1 | G8: =IF(F8<=1,5,IF(F8=2,4,IF(F8=3,3,IF(F8=4,2,IF(F8=5,1,IF(F8>5,0,0)))))) -> 5 | H8: =IF(D8>=$D$3,5,IF(D8<3,0,IF(D8<5,1,IF(D8<7,2,IF(D8<9,3,IF(D8<=$D$3,4,0)))))) -> 1 | I8: =IF(E8>=$E$3,5,IF(E8<2000000,0,IF(E8<=4000000,1,IF(E8<=6000000,2,IF(E8<=8000000,3,IF(E8<=$E$3,4)))))) -> 1 | J8: =IF(AND(G8=5,H8=5,I8=5),"TOP"," ") | K8: =IF(AND(G8>=4,H8>=4), "Sodiq", " ") | L8: =IF(AND(G8<=1,H8<=1), "Yo'qotilgan", " ") | M8: =IF(AND(G8<=3,I8>=3), "Yo'qotishdagi", " ") | N8: =IF(AND((B8-$N$2)>0, F8<=2), "Yangi", " ")
A9: 4876180 | B9: =_xlfn.XLOOKUP(A9,Data!E:E,Data!B:B,0,0,-1) -> 45631 | C9: =_xlfn.XLOOKUP(A9,Data!E:E,Data!B:B) -> 45631 | D9: =COUNTIF(Data!E:E,A9) -> 2 | E9: =SUMIF(Data!E:E,'RFM mijozlar tahlili'!A9,Data!J:J) -> 805106.25 | F9: =ROUND(($F$4-C9)/30,0) -> 1 | G9: =IF(F9<=1,5,IF(F9=2,4,IF(F9=3,3,IF(F9=4,2,IF(F9=5,1,IF(F9>5,0,0)))))) -> 5 | H9: =IF(D9>=$D$3,5,IF(D9<3,0,IF(D9<5,1,IF(D9<7,2,IF(D9<9,3,IF(D9<=$D$3,4,0)))))) -> 0 | I9: =IF(E9>=$E$3,5,IF(E9<2000000,0,IF(E9<=4000000,1,IF(E9<=6000000,2,IF(E9<=8000000,3,IF(E9<=$E$3,4)))))) -> 0 | J9: =IF(AND(G9=5,H9=5,I9=5),"TOP"," ") | K9: =IF(AND(G9>=4,H9>=4), "Sodiq", " ") | L9: =IF(AND(G9<=1,H9<=1), "Yo'qotilgan", " ") | M9: =IF(AND(G9<=3,I9>=3), "Yo'qotishdagi", " ") | N9: =IF(AND((B9-$N$2)>0, F9<=2), "Yangi", " ") -> Yangi
A10: 4876600 | B10: =_xlfn.XLOOKUP(A10,Data!E:E,Data!B:B,0,0,-1) -> 45503 | C10: =_xlfn.XLOOKUP(A10,Data!E:E,Data!B:B) -> 45636 | D10: =COUNTIF(Data!E:E,A10) -> 42 | E10: =SUMIF(Data!E:E,'RFM mijozlar tahlili'!A10,Data!J:J) -> 44252449 | F10: =ROUND(($F$4-C10)/30,0) -> 1 | G10: =IF(F10<=1,5,IF(F10=2,4,IF(F10=3,3,IF(F10=4,2,IF(F10=5,1,IF(F10>5,0,0)))))) -> 5 | H10: =IF(D10>=$D$3,5,IF(D10<3,0,IF(D10<5,1,IF(D10<7,2,IF(D10<9,3,IF(D10<=$D$3,4,0)))))) -> 5 | I10: =IF(E10>=$E$3,5,IF(E10<2000000,0,IF(E10<=4000000,1,IF(E10<=6000000,2,IF(E10<=8000000,3,IF(E10<=$E$3,4)))))) -> 5 | J10: =IF(AND(G10=5,H10=5,I10=5),"TOP"," ") -> TOP | K10: =IF(AND(G10>=4,H10>=4), "Sodiq", " ") -> Sodiq | L10: =IF(AND(G10<=1,H10<=1), "Yo'qotilgan", " ") | M10: =IF(AND(G10<=3,I10>=3), "Yo'qotishdagi", " ") | N10: =IF(AND((B10-$N$2)>0, F10<=2), "Yangi", " ")
A11: 4878657 | B11: =_xlfn.XLOOKUP(A11,Data!E:E,Data!B:B,0,0,-1) -> 45595 | C11: =_xlfn.XLOOKUP(A11,Data!E:E,Data!B:B) -> 45644 | D11: =COUNTIF(Data!E:E,A11) -> 8 | E11: =SUMIF(Data!E:E,'RFM mijozlar tahlili'!A11,Data!J:J) -> 4790382.2 | F11: =ROUND(($F$4-C11)/30,0) -> 1 | G11: =IF(F11<=1,5,IF(F11=2,4,IF(F11=3,3,IF(F11=4,2,IF(F11=5,1,IF(F11>5,0,0)))))) -> 5 | H11: =IF(D11>=$D$3,5,IF(D11<3,0,IF(D11<5,1,IF(D11<7,2,IF(D11<9,3,IF(D11<=$D$3,4,0)))))) -> 3 | I11: =IF(E11>=$E$3,5,IF(E11<2000000,0,IF(E11<=4000000,1,IF(E11<=6000000,2,IF(E11<=8000000,3,IF(E11<=$E$3,4)))))) -> 2 | J11: =IF(AND(G11=5,H11=5,I11=5),"TOP"," ") | K11: =IF(AND(G11>=4,H11>=4), "Sodiq", " ") | L11: =IF(AND(G11<=1,H11<=1), "Yo'qotilgan", " ") | M11: =IF(AND(G11<=3,I11>=3), "Yo'qotishdagi", " ") | N11: =IF(AND((B11-$N$2)>0, F11<=2), "Yangi", " ") -> Yangi
A12: 4876098 | B12: =_xlfn.XLOOKUP(A12,Data!E:E,Data!B:B,0,0,-1) -> 45313 | C12: =_xlfn.XLOOKUP(A12,Data!E:E,Data!B:B) -> 45645 | D12: =COUNTIF(Data!E:E,A12) -> 47 | E12: =SUMIF(Data!E:E,'RFM mijozlar tahlili'!A12,Data!J:J) -> 85212857 | F12: =ROUND(($F$4-C12)/30,0) -> 1 | G12: =IF(F12<=1,5,IF(F12=2,4,IF(F12=3,3,IF(F12=4,2,IF(F12=5,1,IF(F12>5,0,0)))))) -> 5 | H12: =IF(D12>=$D$3,5,IF(D12<3,0,IF(D12<5,1,IF(D12<7,2,IF(D12<9,3,IF(D12<=$D$3,4,0)))))) -> 5 | I12: =IF(E12>=$E$3,5,IF(E12<2000000,0,IF(E12<=4000000,1,IF(E12<=6000000,2,IF(E12<=8000000,3,IF(E12<=$E$3,4)))))) -> 5 | J12: =IF(AND(G12=5,H12=5,I12=5),"TOP"," ") -> TOP | K12: =IF(AND(G12>=4,H12>=4), "Sodiq", " ") -> Sodiq | L12: =IF(AND(G12<=1,H12<=1), "Yo'qotilgan", " ") | M12: =IF(AND(G12<=3,I12>=3), "Yo'qotishdagi", " ") | N12: =IF(AND((B12-$N$2)>0, F12<=2), "Yangi", " ")
A13: 4878586 | B13: =_xlfn.XLOOKUP(A13,Data!E:E,Data!B:B,0,0,-1) -> 45377 | C13: =_xlfn.XLOOKUP(A13,Data!E:E,Data!B:B) -> 45651 | D13: =COUNTIF(Data!E:E,A13) -> 8 | E13: =SUMIF(Data!E:E,'RFM mijozlar tahlili'!A13,Data!J:J) -> 1232787.5 | F13: =ROUND(($F$4-C13)/30,0) -> 0 | G13: =IF(F13<=1,5,IF(F13=2,4,IF(F13=3,3,IF(F13=4,2,IF(F13=5,1,IF(F13>5,0,0)))))) -> 5 | H13: =IF(D13>=$D$3,5,IF(D13<3,0,IF(D13<5,1,IF(D13<7,2,IF(D13<9,3,IF(D13<=$D$3,4,0)))))) -> 3 | I13: =IF(E13>=$E$3,5,IF(E13<2000000,0,IF(E13<=4000000,1,IF(E13<=6000000,2,IF(E13<=8000000,3,IF(E13<=$E$3,4)))))) -> 0 | J13: =IF(AND(G13=5,H13=5,I13=5),"TOP"," ") | K13: =IF(AND(G13>=4,H13>=4), "Sodiq", " ") | L13: =IF(AND(G13<=1,H13<=1), "Yo'qotilgan", " ") | M13: =IF(AND(G13<=3,I13>=3), "Yo'qotishdagi", " ") | N13: =IF(AND((B13-$N$2)>0, F13<=2), "Yangi", " ")
A14: 7787121 | B14: =_xlfn.XLOOKUP(A14,Data!E:E,Data!B:B,0,0,-1) -> 45588 | C14: =_xlfn.XLOOKUP(A14,Data!E:E,Data!B:B) -> 45627 | D14: =COUNTIF(Data!E:E,A14) -> 17 | E14: =SUMIF(Data!E:E,'RFM mijozlar tahlili'!A14,Data!J:J) -> 5247626.7 | F14: =ROUND(($F$4-C14)/30,0) -> 1 | G14: =IF(F14<=1,5,IF(F14=2,4,IF(F14=3,3,IF(F14=4,2,IF(F14=5,1,IF(F14>5,0,0)))))) -> 5 | H14: =IF(D14>=$D$3,5,IF(D14<3,0,IF(D14<5,1,IF(D14<7,2,IF(D14<9,3,IF(D14<=$D$3,4,0)))))) -> 5 | I14: =IF(E14>=$E$3,5,IF(E14<2000000,0,IF(E14<=4000000,1,IF(E14<=6000000,2,IF(E14<=8000000,3,IF(E14<=$E$3,4)))))) -> 2 | J14: =IF(AND(G14=5,H14=5,I14=5),"TOP"," ") | K14: =IF(AND(G14>=4,H14>=4), "Sodiq", " ") -> Sodiq | L14: =IF(AND(G14<=1,H14<=1), "Yo'qotilgan", " ") | M14: =IF(AND(G14<=3,I14>=3), "Yo'qotishdagi", " ") | N14: =IF(AND((B14-$N$2)>0, F14<=2), "Yangi", " ") -> Yangi
A15: 7503974 | B15: =_xlfn.XLOOKUP(A15,Data!E:E,Data!B:B,0,0,-1) -> 45620 | C15: =_xlfn.XLOOKUP(A15,Data!E:E,Data!B:B) -> 45627 | D15: =COUNTIF(Data!E:E,A15) -> 7 | E15: =SUMIF(Data!E:E,'RFM mijozlar tahlili'!A15,Data!J:J) -> -251532.88 | F15: =ROUND(($F$4-C15)/30,0) -> 1 | G15: =IF(F15<=1,5,IF(F15=2,4,IF(F15=3,3,IF(F15=4,2,IF(F15=5,1,IF(F15>5,0,0)))))) -> 5 | H15: =IF(D15>=$D$3,5,IF(D15<3,0,IF(D15<5,1,IF(D15<7,2,IF(D15<9,3,IF(D15<=$D$3,4,0)))))) -> 3 | I15: =IF(E15>=$E$3,5,IF(E15<2000000,0,IF(E15<=4000000,1,IF(E15<=6000000,2,IF(E15<=8000000,3,IF(E15<=$E$3,4)))))) -> 0 | J15: =IF(AND(G15=5,H15=5,I15=5),"TOP"," ") | K15: =IF(AND(G15>=4,H15>=4), "Sodiq", " ") | L15: =IF(AND(G15<=1,H15<=1), "Yo'qotilgan", " ") | M15: =IF(AND(G15<=3,I15>=3), "Yo'qotishdagi", " ") | N15: =IF(AND((B15-$N$2)>0, F15<=2), "Yangi", " ") -> Yangi
A16: 7242425 | B16: =_xlfn.XLOOKUP(A16,Data!E:E,Data!B:B,0,0,-1) -> 45631 | C16: =_xlfn.XLOOKUP(A16,Data!E:E,Data!B:B) -> 45631 | D16: =COUNTIF(Data!E:E,A16) -> 6 | E16: =SUMIF(Data!E:E,'RFM mijozlar tahlili'!A16,Data!J:J) -> 2012765.6 | F16: =ROUND(($F$4-C16)/30,0) -> 1 | G16: =IF(F16<=1,5,IF(F16=2,4,IF(F16=3,3,IF(F16=4,2,IF(F16=5,1,IF(F16>5,0,0)))))) -> 5 | H16: =IF(D16>=$D$3,5,IF(D16<3,0,IF(D16<5,1,IF(D16<7,2,IF(D16<9,3,IF(D16<=$D$3,4,0)))))) -> 2 | I16: =IF(E16>=$E$3,5,IF(E16<2000000,0,IF(E16<=4000000,1,IF(E16<=6000000,2,IF(E16<=8000000,3,IF(E16<=$E$3,4)))))) -> 1 | J16: =IF(AND(G16=5,H16=5,I16=5),"TOP"," ") | K16: =IF(AND(G16>=4,H16>=4), "Sodiq", " ") | L16: =IF(AND(G16<=1,H16<=1), "Yo'qotilgan", " ") | M16: =IF(AND(G16<=3,I16>=3), "Yo'qotishdagi", " ") | N16: =IF(AND((B16-$N$2)>0, F16<=2), "Yangi", " ") -> Yangi
A17: 7241129 | B17: =_xlfn.XLOOKUP(A17,Data!E:E,Data!B:B,0,0,-1) -> 45595 | C17: =_xlfn.XLOOKUP(A17,Data!E:E,Data!B:B) -> 45635 | D17: =COUNTIF(Data!E:E,A17) -> 6 | E17: =SUMIF(Data!E:E,'RFM mijozlar tahlili'!A17,Data!J:J) -> 23067651 | F17: =ROUND(($F$4-C17)/30,0) -> 1 | G17: =IF(F17<=1,5,IF(F17=2,4,IF(F17=3,3,IF(F17=4,2,IF(F17=5,1,IF(F17>5,0,0)))))) -> 5 | H17: =IF(D17>=$D$3,5,IF(D17<3,0,IF(D17<5,1,IF(D17<7,2,IF(D17<9,3,IF(D17<=$D$3,4,0)))))) -> 2 | I17: =IF(E17>=$E$3,5,IF(E17<2000000,0,IF(E17<=4000000,1,IF(E17<=6000000,2,IF(E17<=8000000,3,IF(E17<=$E$3,4)))))) -> 5 | J17: =IF(AND(G17=5,H17=5,I17=5),"TOP"," ") | K17: =IF(AND(G17>=4,H17>=4), "Sodiq", " ") | L17: =IF(AND(G17<=1,H17<=1), "Yo'qotilgan", " ") | M17: =IF(AND(G17<=3,I17>=3), "Yo'qotishdagi", " ") | N17: =IF(AND((B17-$N$2)>0, F17<=2), "Yangi", " ") -> Yangi
... A534: 4873376 | B534: =_xlfn.XLOOKUP(A534,Data!E:E,Data!B:B,0,0,-1) -> 45319 | C534: =_xlfn.XLOOKUP(A534,Data!E:E,Data!B:B) -> 45319 | D534: =COUNTIF(Data!E:E,A534) -> 2 | E534: =SUMIF(Data!E:E,'RFM mijozlar tahlili'!A534,Data!J:J) -> 1249874.7 | F534: =ROUND(($F$4-C534)/30,0) -> 11 | G534: =IF(F534<=1,5,IF(F534=2,4,IF(F534=3,3,IF(F534=4,2,IF(F534=5,1,IF(F534>5,0,0)))))) -> 0 | H534: =IF(D534>=$D$3,5,IF(D534<3,0,IF(D534<5,1,IF(D534<7,2,IF(D534<9,3,IF(D534<=$D$3,4,0)))))) -> 0 | I534: =IF(E534>=$E$3,5,IF(E534<2000000,0,IF(E534<=4000000,1,IF(E534<=6000000,2,IF(E534<=8000000,3,IF(E534<=$E$3,4)))))) -> 0 | J534: =IF(AND(G534=5,H534=5,I534=5),"TOP"," ") | K534: =IF(AND(G534>=4,H534>=4), "Sodiq", " ") | L534: =IF(AND(G534<=1,H534<=1), "Yo'qotilgan", " ") -> Yo'qotilgan | M534: =IF(AND(G534<=3,I534>=3), "Yo'qotishdagi", " ") | N534: =IF(AND((B534-$N$2)>0, F534<=2), "Yangi", " ")

Sheet Hulosa
A1: Birinchi qarashda hammasi mantiqiy ko'rinadi — 530 ta mijoz bor, ularning atigi 20 tasi "Top mijozlar" toifasiga tushadi, 129 tasi esa allaqachon "qaytib kelmaydigan" deb belgilangan. Odatiy holat, har qanday RFM tahlilida shunday bo'ladi.
A3: Lekin daromadga qarasam, boshqacha manzara chiqdi. "Potensial yo'qotishdagi mijozlar" — ya'ni ilgari faol xarid qilgan, lekin oxirgi paytlarda kamroq ko'rinayotgan mijozlar guruhi — bor-yo'g'i 90 kishi, bu umumiy mijozlarning 17 foizi. Lekin ular kompaniyaning jami daromadining 68 foizini ta'minlaydi. Bir necha marta qayta hisoblab ko'rdim, xato emas — 4.1 milliard so'mdan ortiq, 6 milliardlik umumiy daromaddan.
A5: Solishtirish uchun: "Top mijozlar" (eng sodiq, eng faol 20 kishi) atigi 11 foiz daromad beradi. Ya'ni kompaniyaning haqiqiy pul ishlab beruvchi qismi "Top" emas, balki hozir sekin-asta uzoqlashayotgan o'sha 90 kishi ekan.
A7: Bu, mening nazarimda, oddiy statistika emas — bu signal. Agar shu 90 kishidan hatto 10-15 tasi butunlay ketib qolsa, kompaniya daromadining sezilarli qismini yo'qotadi, va buni hech qanday yangi mijoz yoki hatto "Top" segment tezda qoplab bera olmaydi, chunki ular hajman juda kichik.
A9: Shuning uchun, agar men shu tahlilni ko'rgan bo'lsam va qaror qabul qiladigan joyda tursam, birinchi navbatda shu 90 kishiga individual yondashuv kerak deb o'ylardim — nega ular kamroq xarid qilyapti, degan savolga javob topish. Umumiy chegirma yoki ommaviy SMS emas, balki har birining oldingi xarid tarixiga qarab shaxsiy taklif. Bu ancha ko'p mehnat talab qiladi, lekin 68 foiz daromad gap-so'z emas — buni saqlab qolish narigi tomondagi 300+ "oddiy" mijozni jalb qilishdan ancha arzonga tushadi.
A11: Qolgan segmentlar haqida qisqacha: "Yangi mijozlar" (57 kishi) hozircha kichik hissa qo'shyapti (2 foiz atrofida), bu normal — ular hali ulgurmagan. "Qaytib kelmaydiganlar" (129 kishi, eng katta guruh sonlab) daromadga deyarli ta'sir qilmaydi (3 foizdan kam) — demak ularni qaytarishga urinish o'z vaqti va resursini oqlamasligi mumkin, kichikroq byudjet bilan avtomatik email/SMS kampaniya yetarli.
